<?xml version="1.0" encoding="utf-8"?>
<robot
  name="GEN3-7DOF_BRAKES_NO-VISION_URDF_ARM_V01">
  <link
    name="base_link">
    <inertial>
      <origin
        xyz="-0.00075876 -0.00019207 0.09605351"
        rpy="0 0 0" />
      <mass
        value="1.7565703" />
      <inertia
        ixx="0.00562309"
        ixy="5.96E-06"
        ixz="6.235E-05"
        iyy="0.00551518"
        iyz="6.09E-06"
        izz="0.00205231" />
    </inertial>
    <visual>
      <origin
        xyz="0 0 0"
        rpy="0 0 0" />
      <geometry>
        <mesh
          filename="package://kortex_description/arms/gen3/7dof/meshes/base_link.STL" />
      </geometry>
      <material
        name="">
        <color
          rgba="1 1 1 1" />
      </material>
    </visual>
    <collision>
      <origin
        xyz="0 0 0"
        rpy="0 0 0" />
      <geometry>
        <mesh
          filename="package://kortex_description/arms/gen3/7dof/meshes/base_link.STL" />
      </geometry>
    </collision>
  </link>
  <link
    name="shoulder_link">
    <inertial>
      <origin
        xyz="-2.522E-05 -0.00759535 -0.08865077"
        rpy="0 0 0" />
      <mass
        value="1.46990145" />
      <inertia
        ixx="0.00432687"
        ixy="2.5E-07"
        ixz="9.4E-07"
        iyy="0.00447028"
        iyz="0.0001016"
        izz="0.00145324" />
    </inertial>
    <visual>
      <origin
        xyz="0 0 0"
        rpy="0 0 0" />
      <geometry>
        <mesh
          filename="package://kortex_description/arms/gen3/7dof/meshes/shoulder_link.STL" />
      </geometry>
      <material
        name="">
        <color
          rgba="0.84706 0.8549 0.85098 1" />
      </material>
    </visual>
    <collision>
      <origin
        xyz="0 0 0"
        rpy="0 0 0" />
      <geometry>
        <mesh
          filename="package://kortex_description/arms/gen3/7dof/meshes/shoulder_link.STL" />
      </geometry>
    </collision>
  </link>
  <joint
    name="joint_1"
    type="revolute">
    <origin
      xyz="0 0 0.15643"
      rpy="3.1416 0 0" />
    <parent
      link="base_link" />
    <child
      link="shoulder_link" />
    <axis
      xyz="0 0 1" />
    <limit
      lower="-3.14"
      upper="3.14"
      effort="390"
      velocity="1.3963" />
  </joint>
  <link
    name="half_arm_1_link">
    <inertial>
      <origin
        xyz="-4.533E-05 -0.12951716 -0.01354356"
        rpy="0 0 0" />
      <mass
        value="1.2357745" />
      <inertia
        ixx="0.0115879"
        ixy="-1.05E-06"
        ixz="5E-08"
        iyy="0.00104574"
        iyz="-0.00096902"
        izz="0.0116684" />
    </inertial>
    <visual>
      <origin
        xyz="0 0 0"
        rpy="0 0 0" />
      <geometry>
        <mesh
          filename="package://kortex_description/arms/gen3/7dof/meshes/half_arm_1_link.STL" />
      </geometry>
      <material
        name="">
        <color
          rgba="0.75294 0.75294 0.75294 1" />
      </material>
    </visual>
    <collision>
      <origin
        xyz="0 0 0"
        rpy="0 0 0" />
      <geometry>
        <mesh
          filename="package://kortex_description/arms/gen3/7dof/meshes/half_arm_1_link.STL" />
      </geometry>
    </collision>
  </link>
  <joint
    name="joint_2"
    type="revolute">
    <origin
      xyz="0 0.005375 -0.12838"
      rpy="1.5708 0 0" />
    <parent
      link="shoulder_link" />
    <child
      link="half_arm_1_link" />
    <axis
      xyz="0 0 1" />
    <limit
      lower="-2.24"
      upper="2.24"
      effort="390"
      velocity="1.3963" />
  </joint>
  <link
    name="half_arm_2_link">
    <inertial>
      <origin
        xyz="-4.533E-05 -0.00361448 -0.14407154"
        rpy="0 0 0" />
      <mass
        value="1.2357745" />
      <inertia
        ixx="0.01009873"
        ixy="5.7E-07"
        ixz="1.89E-06"
        iyy="0.01017801"
        iyz="0.00013166"
        izz="0.00104697" />
    </inertial>
    <visual>
      <origin
        xyz="0 0 0"
        rpy="0 0 0" />
      <geometry>
        <mesh
          filename="package://kortex_description/arms/gen3/7dof/meshes/half_arm_2_link.STL" />
      </geometry>
      <material
        name="">
        <color
          rgba="0.75294 0.75294 0.75294 1" />
      </material>
    </visual>
    <collision>
      <origin
        xyz="0 0 0"
        rpy="0 0 0" />
      <geometry>
        <mesh
          filename="package://kortex_description/arms/gen3/7dof/meshes/half_arm_2_link.STL" />
      </geometry>
    </collision>
  </link>
  <joint
    name="joint_3"
    type="revolute">
    <origin
      xyz="0 -0.21038 -0.006375"
      rpy="-1.5708 0 0" />
    <parent
      link="half_arm_1_link" />
    <child
      link="half_arm_2_link" />
    <axis
      xyz="0 0 1" />
    <limit
      lower="-3.14"
      upper="3.14"
      effort="390"
      velocity="1.3963" />
  </joint>
  <link
    name="forearm_link">
    <inertial>
      <origin
        xyz="-0.00030188 -0.104938 -0.01559665"
        rpy="0 0 0" />
      <mass
        value="0.89954802" />
      <inertia
        ixx="0.00889854"
        ixy="1.98E-05"
        ixz="-2.39E-06"
        iyy="0.00060297"
        iyz="-0.00074456"
        izz="0.00898975" />
    </inertial>
    <visual>
      <origin
        xyz="0 0 0"
        rpy="0 0 0" />
      <geometry>
        <mesh
          filename="package://kortex_description/arms/gen3/7dof/meshes/forearm_link.STL" />
      </geometry>
      <material
        name="">
        <color
          rgba="0.84706 0.8549 0.85098 1" />
      </material>
    </visual>
    <collision>
      <origin
        xyz="0 0 0"
        rpy="0 0 0" />
      <geometry>
        <mesh
          filename="package://kortex_description/arms/gen3/7dof/meshes/forearm_link.STL" />
      </geometry>
    </collision>
  </link>
  <joint
    name="joint_4"
    type="revolute">
    <origin
      xyz="0 0.006375 -0.210375"
      rpy="1.5708 0 0" />
    <parent
      link="half_arm_2_link" />
    <child
      link="forearm_link" />
    <axis
      xyz="0 0 1" />
    <limit
      lower="-2.57"
      upper="2.57"
      effort="390"
      velocity="1.3963" />
  </joint>
  <link
    name="spherical_wrist_1_link">
    <inertial>
      <origin
        xyz="-0.00035363 -0.00659443 -0.07560343"
        rpy="0 0 0" />
      <mass
        value="0.70588351" />
      <inertia
        ixx="0.00145671"
        ixy="3.35E-06"
        ixz="7.62E-06"
        iyy="0.00145189"
        iyz="0.00012055"
        izz="0.00039299" />
    </inertial>
    <visual>
      <origin
        xyz="0 0 0"
        rpy="0 0 0" />
      <geometry>
        <mesh
          filename="package://kortex_description/arms/gen3/7dof/meshes/spherical_wrist_1_link.STL" />
      </geometry>
      <material
        name="">
        <color
          rgba="0.84706 0.8549 0.85098 1" />
      </material>
    </visual>
    <collision>
      <origin
        xyz="0 0 0"
        rpy="0 0 0" />
      <geometry>
        <mesh
          filename="package://kortex_description/arms/gen3/7dof/meshes/spherical_wrist_1_link.STL" />
      </geometry>
    </collision>
  </link>
  <joint
    name="joint_5"
    type="revolute">
    <origin
      xyz="0 -0.208425 -0.006375"
      rpy="-1.5708 0 0" />
    <parent
      link="forearm_link" />
    <child
      link="spherical_wrist_1_link" />
    <axis
      xyz="0 0 1" />
    <limit
      lower="-3.14"
      upper="3.14"
      effort="90"
      velocity="1.2218" />
  </joint>
  <link
    name="spherical_wrist_2_link">
    <inertial>
      <origin
        xyz="-0.00035547 -0.06159424 -0.00850171"
        rpy="0 0 0" />
      <mass
        value="0.70583924" />
      <inertia
        ixx="0.00187208"
        ixy="6.1E-06"
        ixz="-2.17E-06"
        iyy="0.00041077"
        iyz="-0.00033774"
        izz="0.0018494" />
    </inertial>
    <visual>
      <origin
        xyz="0 0 0"
        rpy="0 0 0" />
      <geometry>
        <mesh
          filename="package://kortex_description/arms/gen3/7dof/meshes/spherical_wrist_2_link.STL" />
      </geometry>
      <material
        name="">
        <color
          rgba="0.84706 0.8549 0.85098 1" />
      </material>
    </visual>
    <collision>
      <origin
        xyz="0 0 0"
        rpy="0 0 0" />
      <geometry>
        <mesh
          filename="package://kortex_description/arms/gen3/7dof/meshes/spherical_wrist_2_link.STL" />
      </geometry>
    </collision>
  </link>
  <joint
    name="joint_6"
    type="revolute">
    <origin
      xyz="0 0.00017505 -0.10592505"
      rpy="1.5708 0 0" />
    <parent
      link="spherical_wrist_1_link" />
    <child
      link="spherical_wrist_2_link" />
    <axis
      xyz="0 0 1" />
    <limit
      lower="-2.09"
      upper="2.09"
      effort="90"
      velocity="1.2218" />
  </joint>
  <link
    name="bracelet_link">
    <inertial>
      <origin
        xyz="-0.00027419 -0.01170136 -0.03437502"
        rpy="0 0 0" />
      <mass
        value="0.43504643" />
      <inertia
        ixx="0.00048886"
        ixy="2.59E-06"
        ixz="1.75E-06"
        iyy="0.00029425"
        iyz="8.248E-05"
        izz="0.000542" />
    </inertial>
    <visual>
      <origin
        xyz="0 0 0"
        rpy="0 0 0" />
      <geometry>
        <mesh
          filename="package://kortex_description/arms/gen3/7dof/meshes/bracelet_with_vision_link.STL" />
      </geometry>
      <material
        name="">
        <color
          rgba="0.75294 0.75294 0.75294 1" />
      </material>
    </visual>
    <collision>
      <origin
        xyz="0 0 0"
        rpy="0 0 0" />
      <geometry>
        <mesh
          filename="package://kortex_description/arms/gen3/7dof/meshes/bracelet_with_vision_link.STL" />
      </geometry>
    </collision>
  </link>
  <joint
    name="joint_7"
    type="revolute">
    <origin
      xyz="0 -0.10592505 -0.00017505"
      rpy="-1.5708 0 0" />
    <parent
      link="spherical_wrist_2_link" />
    <child
      link="bracelet_link" />
    <axis
      xyz="0 0 1" />
    <limit
      lower="-3.14"
      upper="3.14"
      effort="90"
      velocity="1.2218" />
  </joint>
  <link
    name="end_effector_link">
    <inertial>
      <origin
        xyz="0 0 0"
        rpy="0 0 0" />
      <mass
        value="0" />
      <inertia
        ixx="0"
        ixy="0"
        ixz="0"
        iyy="0"
        iyz="0"
        izz="0" />
    </inertial>
  </link>
  <joint
    name="end_effector"
    type="fixed">
    <origin
      xyz="0 0 -0.061525"
      rpy="3.1416 0 0" />
    <parent
      link="bracelet_link" />
    <child
      link="end_effector_link" />
    <axis
      xyz="0 0 0" />
  </joint>
  
  

  <!-- ############################################################### -->
  <!-- ############################################################### -->
  <!-- ############################################################### -->
  <!-- HAND -->
  <!-- ############################################################### -->
  <!-- ############################################################### -->
  <!-- ############################################################### -->

  <link
    name="hand_base_link">
    <inertial>
      <origin
        xyz="-0.00119902400080689 0.0676395118380097 -0.000831468763240618"
        rpy="0 0 0" />
      <mass
        value="2.61841951961561" />
      <inertia
        ixx="0.00289488464735745"
        ixy="1.26632522214081E-05"
        ixz="4.75779358553846E-05"
        iyy="0.0015541400089684"
        iyz="2.51442141340795E-05"
        izz="0.00380659471612325" />
    </inertial>
    <visual>
      <origin
        xyz="0 0 0"
        rpy="0 0 0" />
      <geometry>
        <mesh
          filename="package://kortex_description/arms/gen3/7dof/meshes/hand/base_link.STL" />
      </geometry>
      <material
        name="">
        <color
          rgba="0.529411764705882 0.549019607843137 0.549019607843137 1" />
      </material>
    </visual>
    <collision>
      <origin
        xyz="0 0 0"
        rpy="0 0 0" />
      <geometry>
        <mesh
          filename="package://kortex_description/arms/gen3/7dof/meshes/hand/base_link.STL" />
      </geometry>
    </collision>
  </link>

  <joint
    name="hand"
    type="fixed">
    <origin
      xyz="0 0 0"
      rpy="1.5708 0 0" />
    <parent
      link="end_effector_link" />
    <child
      link="hand_base_link" />
    <axis
      xyz="0 0 0" />
  </joint>

  <!--############################################################### -->
  <link
    name="hand_link1">
    <inertial>
      <origin
        xyz="0.0137751250378393 -0.00981394991394148 0.00208430495133732"
        rpy="0 0 0" />
      <mass
        value="0.0848759840699757" />
      <inertia
        ixx="6.02792303641558E-06"
        ixy="4.58047907735606E-07"
        ixz="-1.13414482822443E-06"
        iyy="9.43150541499264E-06"
        iyz="1.07407363059388E-07"
        izz="9.99149179527929E-06" />
    </inertial>
    <visual>
      <origin
        xyz="0 0 0"
        rpy="0 0 0" />
      <geometry>
        <mesh
          filename="package://kortex_description/arms/gen3/7dof/meshes/hand/link1.STL" />
      </geometry>
      <material
        name="">
        <color
          rgba="0.529411764705882 0.549019607843137 0.549019607843137 1" />
      </material>
    </visual>
    <collision>
      <origin
        xyz="0 0 0"
        rpy="0 0 0" />
      <geometry>
        <mesh
          filename="package://kortex_description/arms/gen3/7dof/meshes/hand/link1.STL" />
      </geometry>
    </collision>
  </link>
  <joint
    name="j1"
    type="revolute">
    <origin
      xyz="0.028693 0.069894 0.010325"
      rpy="0 0 0.087266" />
    <parent
      link="hand_base_link" />
    <child
      link="hand_link1" />
    <axis
      xyz="0 1 0" />
    <limit
      lower="-1.785"
      upper="0"
      effort="80"
      velocity="80" />
  </joint>

  <!--############################################################### -->
  <link
    name="hand_link2">
    <inertial>
      <origin
        xyz="4.36100697220887E-09 0.0183171211967979 -0.012870354643197"
        rpy="0 0 0" />
      <mass
        value="0.189071895133877" />
      <inertia
        ixx="4.62451218821649E-05"
        ixy="1.70090875141461E-10"
        ixz="-1.79647819838937E-10"
        iyy="2.71230540243915E-05"
        iyz="1.30744554320643E-05"
        izz="3.14501850290832E-05" />
    </inertial>
    <visual>
      <origin
        xyz="0 0 0"
        rpy="0 0 0" />
      <geometry>
        <mesh
          filename="package://kortex_description/arms/gen3/7dof/meshes/hand/link2.STL" />
      </geometry>
      <material
        name="">
        <color
          rgba="0.529411764705882 0.549019607843137 0.549019607843137 1" />
      </material>
    </visual>
    <collision>
      <origin
        xyz="0 0 0"
        rpy="0 0 0" />
      <geometry>
        <mesh
          filename="package://kortex_description/arms/gen3/7dof/meshes/hand/link2.STL" />
      </geometry>
    </collision>
  </link>
  <joint
    name="j2"
    type="revolute">
    <origin
      xyz="0.02679 -0.0045 0.0045976"
      rpy="3.0557 -1.3935 3.1416" />
    <parent
      link="hand_link1" />
    <child
      link="hand_link2" />
    <axis
      xyz="1 0 0" />
    <limit
      lower="0"
      upper="0.29"
      effort="80"
      velocity="80" />
  </joint>

  <!--############################################################### -->
  <link
    name="hand_link3">
    <inertial>
      <origin
        xyz="-0.00555064313303445 0.00539090806696246 -0.0144478834389504"
        rpy="0 0 0" />
      <mass
        value="0.0765978194144121" />
      <inertia
        ixx="8.30143631907092E-06"
        ixy="-2.64543837885093E-09"
        ixz="6.33140406065459E-10"
        iyy="5.90636128499543E-06"
        iyz="1.96617508560125E-06"
        izz="6.16162484246875E-06" />
    </inertial>
    <visual>
      <origin
        xyz="0 0 0"
        rpy="0 0 0" />
      <geometry>
        <mesh
          filename="package://kortex_description/arms/gen3/7dof/meshes/hand/link3.STL" />
      </geometry>
      <material
        name="">
        <color
          rgba="0.529411764705882 0.549019607843137 0.549019607843137 1" />
      </material>
    </visual>
    <collision>
      <origin
        xyz="0 0 0"
        rpy="0 0 0" />
      <geometry>
        <mesh
          filename="package://kortex_description/arms/gen3/7dof/meshes/hand/link3.STL" />
      </geometry>
    </collision>
  </link>
  <joint
    name="j3"
    type="revolute">
    <origin
      xyz="0.0055478 0.0413 -0.024172"
      rpy="0 0 0" />
    <parent
      link="hand_link2" />
    <child
      link="hand_link3" />
    <axis
      xyz="1 0 0" />
    <limit
      lower="0"
      upper="0.44"
      effort="80"
      velocity="80" />
  </joint>

  <!--############################################################### -->
  <link
    name="hand_link4">
    <inertial>
      <origin
        xyz="-0.0036569973005798 0.0162113209076923 0.000273547127676674"
        rpy="0 0 0" />
      <mass
        value="0.0686348714224919" />
      <inertia
        ixx="7.33254847238726E-06"
        ixy="-2.66340785344831E-12"
        ixz="1.08765083632757E-12"
        iyy="2.87970755794507E-06"
        iyz="5.37142487415021E-07"
        izz="7.422847187087E-06" />
    </inertial>
    <visual>
      <origin
        xyz="0 0 0"
        rpy="0 0 0" />
      <geometry>
        <mesh
          filename="package://kortex_description/arms/gen3/7dof/meshes/hand/link4.STL" />
      </geometry>
      <material
        name="">
        <color
          rgba="0.529411764705882 0.549019607843137 0.549019607843137 1" />
      </material>
    </visual>
    <collision>
      <origin
        xyz="0 0 0"
        rpy="0 0 0" />
      <geometry>
        <mesh
          filename="package://kortex_description/arms/gen3/7dof/meshes/hand/link4.STL" />
      </geometry>
    </collision>
  </link>
  <joint
    name="j4"
    type="revolute">
    <origin
      xyz="0.034276 0.1374 0.001"
      rpy="0 0 0" />
    <parent
      link="hand_base_link" />
    <child
      link="hand_link4" />
    <axis
      xyz="-1 0 0" />
    <limit
      lower="-1.24"
      upper="0"
      effort="80"
      velocity="80" />
  </joint>

  <!--############################################################### -->
  <link
    name="hand_link5">
    <inertial>
      <origin
        xyz="-0.00450223853979242 0.0245775687164807 0.00926785909974535"
        rpy="0 0 0" />
      <mass
        value="0.0755292904950472" />
      <inertia
        ixx="1.57108591312927E-05"
        ixy="-2.65891509368178E-09"
        ixz="-5.06696550628499E-10"
        iyy="3.78223232864861E-06"
        iyz="-3.96130529426087E-06"
        izz="1.44759601190385E-05" />
    </inertial>
    <visual>
      <origin
        xyz="0 0 0"
        rpy="0 0 0" />
      <geometry>
        <mesh
          filename="package://kortex_description/arms/gen3/7dof/meshes/hand/link5.STL" />
      </geometry>
      <material
        name="">
        <color
          rgba="0.529411764705882 0.549019607843137 0.549019607843137 1" />
      </material>
    </visual>
    <collision>
      <origin
        xyz="0 0 0"
        rpy="0 0 0" />
      <geometry>
        <mesh
          filename="package://kortex_description/arms/gen3/7dof/meshes/hand/link5.STL" />
      </geometry>
    </collision>
  </link>
  <joint
    name="j5"
    type="revolute">
    <origin
      xyz="0.00084336 0.031988 -0.0026473"
      rpy="0 0 0" />
    <parent
      link="hand_link4" />
    <child
      link="hand_link5" />
    <axis
      xyz="-1 0 0" />
    <limit
      lower="-1.57"
      upper="0"
      effort="80"
      velocity="80" />
  </joint>

  <!--############################################################### -->
  <link
    name="hand_link6">
    <inertial>
      <origin
        xyz="-0.00365699730057982 0.0162113209076926 0.00027354712767666"
        rpy="0 0 0" />
      <mass
        value="0.0686348714224907" />
      <inertia
        ixx="7.33254847238703E-06"
        ixy="-2.66340787168868E-12"
        ixz="1.08765081322438E-12"
        iyy="2.87970755794502E-06"
        iyz="5.37142487415025E-07"
        izz="7.42284718708672E-06" />
    </inertial>
    <visual>
      <origin
        xyz="0 0 0"
        rpy="0 0 0" />
      <geometry>
        <mesh
          filename="package://kortex_description/arms/gen3/7dof/meshes/hand/link6.STL" />
      </geometry>
      <material
        name="">
        <color
          rgba="0.529411764705882 0.549019607843137 0.549019607843137 1" />
      </material>
    </visual>
    <collision>
      <origin
        xyz="0 0 0"
        rpy="0 0 0" />
      <geometry>
        <mesh
          filename="package://kortex_description/arms/gen3/7dof/meshes/hand/link6.STL" />
      </geometry>
    </collision>
  </link>
  <joint
    name="j6"
    type="revolute">
    <origin
      xyz="0.012276 0.14055 0.001"
      rpy="0 0 0" />
    <parent
      link="hand_base_link" />
    <child
      link="hand_link6" />
    <axis
      xyz="-1 0 0" />
    <limit
      lower="-1.24"
      upper="0"
      effort="80"
      velocity="80" />
  </joint>

  <!--############################################################### -->
  <link
    name="hand_link7">
    <inertial>
      <origin
        xyz="-0.00365887353581443 0.0268852930825247 0.00907687418344099"
        rpy="0 0 0" />
      <mass
        value="0.0755292952305594" />
      <inertia
        ixx="1.57108601660693E-05"
        ixy="-2.65847990684081E-09"
        ixz="-5.06510838631664E-10"
        iyy="3.78223268736312E-06"
        iyz="-3.96130566158398E-06"
        izz="1.44759612204894E-05" />
    </inertial>
    <visual>
      <origin
        xyz="0 0 0"
        rpy="0 0 0" />
      <geometry>
        <mesh
          filename="package://kortex_description/arms/gen3/7dof/meshes/hand/link7.STL" />
      </geometry>
      <material
        name="">
        <color
          rgba="0.529411764705882 0.549019607843137 0.549019607843137 1" />
      </material>
    </visual>
    <collision>
      <origin
        xyz="0 0 0"
        rpy="0 0 0" />
      <geometry>
        <mesh
          filename="package://kortex_description/arms/gen3/7dof/meshes/hand/link7.STL" />
      </geometry>
    </collision>
  </link>
  <joint
    name="j7"
    type="revolute">
    <origin
      xyz="0 0.02968 -0.0024563"
      rpy="0 0 0" />
    <parent
      link="hand_link6" />
    <child
      link="hand_link7" />
    <axis
      xyz="-1 0 0" />
    <limit
      lower="-1.57"
      upper="0"
      effort="80"
      velocity="80" />
  </joint>

  <!--############################################################### -->
  <link
    name="hand_link8">
    <inertial>
      <origin
        xyz="-0.00365699730057996 0.0162113209076925 0.000273547127676729"
        rpy="0 0 0" />
      <mass
        value="0.0686348714224909" />
      <inertia
        ixx="7.33254847238706E-06"
        ixy="-2.66340798155937E-12"
        ixz="1.08765082198048E-12"
        iyy="2.87970755794502E-06"
        iyz="5.37142487415066E-07"
        izz="7.42284718708676E-06" />
    </inertial>
    <visual>
      <origin
        xyz="0 0 0"
        rpy="0 0 0" />
      <geometry>
        <mesh
          filename="package://kortex_description/arms/gen3/7dof/meshes/hand/link8.STL" />
      </geometry>
      <material
        name="">
        <color
          rgba="0.529411764705882 0.549019607843137 0.549019607843137 1" />
      </material>
    </visual>
    <collision>
      <origin
        xyz="0 0 0"
        rpy="0 0 0" />
      <geometry>
        <mesh
          filename="package://kortex_description/arms/gen3/7dof/meshes/hand/link8.STL" />
      </geometry>
    </collision>
  </link>
  <joint
    name="j8"
    type="revolute">
    <origin
      xyz="-0.009724 0.1374 0.001"
      rpy="0 0 0" />
    <parent
      link="hand_base_link" />
    <child
      link="hand_link8" />
    <axis
      xyz="-1 0 0" />
    <limit
      lower="-1.24"
      upper="0"
      effort="80"
      velocity="80" />
  </joint>

  <!--############################################################### -->
  <link
    name="hand_link9">
    <inertial>
      <origin
        xyz="-0.00365887394452614 0.0268852939054231 0.00907687452350932"
        rpy="0 0 0" />
      <mass
        value="0.0755292904717439" />
      <inertia
        ixx="1.57108591192926E-05"
        ixy="-2.6589152266971E-09"
        ixz="-5.06696620209176E-10"
        iyy="3.78223232752807E-06"
        iyz="-3.96130529054741E-06"
        izz="1.44759601085164E-05" />
    </inertial>
    <visual>
      <origin
        xyz="0 0 0"
        rpy="0 0 0" />
      <geometry>
        <mesh
          filename="package://kortex_description/arms/gen3/7dof/meshes/hand/link9.STL" />
      </geometry>
      <material
        name="">
        <color
          rgba="0.529411764705882 0.549019607843137 0.549019607843137 1" />
      </material>
    </visual>
    <collision>
      <origin
        xyz="0 0 0"
        rpy="0 0 0" />
      <geometry>
        <mesh
          filename="package://kortex_description/arms/gen3/7dof/meshes/hand/link9.STL" />
      </geometry>
    </collision>
  </link>
  <joint
    name="j9"
    type="revolute">
    <origin
      xyz="0 0.02968 -0.0024563"
      rpy="0 0 0" />
    <parent
      link="hand_link8" />
    <child
      link="hand_link9" />
    <axis
      xyz="-1 0 0" />
    <limit
      lower="-1.57"
      upper="0"
      effort="80"
      velocity="80" />
  </joint>

  <!--############################################################### -->
  <link
    name="hand_link10">
    <inertial>
      <origin
        xyz="-0.0036569973005798 0.0162113209076923 0.000273547127676674"
        rpy="0 0 0" />
      <mass
        value="0.0686348714224923" />
      <inertia
        ixx="7.33254847238732E-06"
        ixy="-2.66340783682772E-12"
        ixz="1.08765084134209E-12"
        iyy="2.87970755794509E-06"
        iyz="5.37142487415014E-07"
        izz="7.42284718708707E-06" />
    </inertial>
    <visual>
      <origin
        xyz="0 0 0"
        rpy="0 0 0" />
      <geometry>
        <mesh
          filename="package://kortex_description/arms/gen3/7dof/meshes/hand/link10.STL" />
      </geometry>
      <material
        name="">
        <color
          rgba="0.529411764705882 0.549019607843137 0.549019607843137 1" />
      </material>
    </visual>
    <collision>
      <origin
        xyz="0 0 0"
        rpy="0 0 0" />
      <geometry>
        <mesh
          filename="package://kortex_description/arms/gen3/7dof/meshes/hand/link10.STL" />
      </geometry>
    </collision>
  </link>
  <joint
    name="j10"
    type="revolute">
    <origin
      xyz="-0.031724 0.13417 0.001"
      rpy="0 0 0" />
    <parent
      link="hand_base_link" />
    <child
      link="hand_link10" />
    <axis
      xyz="-1 0 0" />
    <limit
      lower="-1.24"
      upper="0"
      effort="80"
      velocity="80" />
  </joint>

  <!--############################################################### -->
  <link
    name="hand_link11">
    <inertial>
      <origin
        xyz="-0.00450223813308796 0.0245775695404106 0.00926785944008141"
        rpy="0 0 0" />
      <mass
        value="0.0755292857716501" />
      <inertia
        ixx="1.57108580998035E-05"
        ixy="-2.6584823064413E-09"
        ixz="-5.06511787908576E-10"
        iyy="3.78223197131172E-06"
        iyz="-3.96130492810724E-06"
        izz="1.44759590213488E-05" />
    </inertial>
    <visual>
      <origin
        xyz="0 0 0"
        rpy="0 0 0" />
      <geometry>
        <mesh
          filename="package://kortex_description/arms/gen3/7dof/meshes/hand/link11.STL" />
      </geometry>
      <material
        name="">
        <color
          rgba="0.529411764705882 0.549019607843137 0.549019607843137 1" />
      </material>
    </visual>
    <collision>
      <origin
        xyz="0 0 0"
        rpy="0 0 0" />
      <geometry>
        <mesh
          filename="package://kortex_description/arms/gen3/7dof/meshes/hand/link11.STL" />
      </geometry>
    </collision>
  </link>
  <joint
    name="j11"
    type="revolute">
    <origin
      xyz="0.00084336 0.031988 -0.0026473"
      rpy="0 0 0" />
    <parent
      link="hand_link10" />
    <child
      link="hand_link11" />
    <axis
      xyz="-1 0 0" />
    <limit
      lower="-1.57"
      upper="0"
      effort="80"
      velocity="80" />
  </joint>

  <!-- ############################################################### -->
  <!-- ############################################################### -->
  <!-- ############################################################### -->
  <!-- HAND -->
  <!-- ############################################################### -->
  <!-- ############################################################### -->
  <!-- ############################################################### -->

</robot>